<?xml version="1.0"?>
<robot xmlns:xacro="http://wiki.ros.org/xacro">
  <xacro:macro name="agv" params="
    agv_number
    y_position">
    
    <xacro:include filename="$(find ariac_description)/urdf/agv/agv.ros2_control.xacro"/>

    <!-- Run ROS2 control macro -->
    <xacro:agv_ros2_control name="${agv_number}"/>

    <link name="${agv_number}_track">
      <inertial>
        <mass value="100"/>
        <inertia ixx="1.0" ixy="0.0" ixz="0.0" iyy="1.0" iyz="0.0" izz="1.0"/>
      </inertial>
    </link>

    <link name="${agv_number}_base">      
      <visual>
        <geometry>
          <mesh filename="file://$(find ariac_description)/meshes/agv/robot.dae" scale="1 -1 1"/>
        </geometry>
      </visual>
      <collision>
        <geometry>
          <mesh filename="file://$(find ariac_description)/meshes/agv/robot.dae" scale="1 -1 1"/>
        </geometry>
      </collision>
      <inertial>
        <origin xyz="0 0 0" rpy="0 0 0"/>
        <mass value="50.0"/>
        <inertia
            ixx="4.525499333333333" ixy="0.0" ixz="0.0"
            iyy="1.4504741933333334" iyz="0.0"
            izz="5.6426401933333326"/>
      </inertial>
    </link>

    <link name="${agv_number}_tray">
      <visual>
        <geometry>
          <mesh filename="file://$(find ariac_description)/meshes/agv/tray.stl" scale="1 1 1"/>
        </geometry>
        <material name="Grey"/>
      </visual>
      
      <collision name="${agv_number}_tray_collision">
        <geometry>
          <mesh filename="file://$(find ariac_description)/meshes/agv/tray.stl" scale="1 1 1"/>
        </geometry>
      </collision>

      <collision name="${agv_number}_tray_collision1">
        <geometry>
          <mesh filename="file://$(find ariac_description)/meshes/agv/contact_sensor.stl" scale="1 1 1"/>
        </geometry>
      </collision>
      
      <inertial>
        <origin xyz="0 0 0" rpy="0 0 0"/>
        <mass value="1"/>
        <inertia ixx="0.0408" ixy="0.0" ixz="0.0" iyy="0.02084" iyz="0.0" izz="0.0616"/>
      </inertial>
    </link>

    <gazebo reference="${agv_number}_tray">
      <sensor type="contact" name="bumper">
        <update_rate>10</update_rate>
        <contact>
          <collision>${agv_number}_tray_collision1_collision_1</collision>
        </contact>
      </sensor>
    </gazebo>

    <gazebo reference="${agv_number}_tray">
      <material>Gazebo/Gray</material>
    </gazebo>

    <joint name="${agv_number}_world_to_track" type="fixed">
      <parent link="world"/>
      <child link="${agv_number}_track"/>
      <origin xyz="-2.27 ${y_position} 0.01" rpy="0.0 0.0 ${pi/2}"/>
    </joint>

    <joint name="${agv_number}_joint" type="prismatic">
      <axis xyz="0 1 0"/>
      <origin xyz="0.0 0.0 0.0"/>
      <parent link="${agv_number}_track"/>
      <child link="${agv_number}_base"/>
      <limit effort="1000.0" lower="0" upper="18" velocity="8"/>
      <dynamics damping="20.0" friction="500.0" />
    </joint>

    <joint name="${agv_number}_tray_joint" type="revolute">
      <axis xyz="0 0 1"/>
      <parent link="${agv_number}_base"/>
      <child link="${agv_number}_tray"/>
      <limit lower="-.001" upper=".001" effort="0" velocity="0" />
      <origin xyz="0 -0.2 .75" rpy="0.0 0.0 0.0"/>
    </joint>

    <!-- Create AGV plugin -->
    <gazebo>
      <plugin filename="libagv_plugin.so" name="${agv_number}_plugin">
        <ros>
        </ros>
        <agv_number>${agv_number}</agv_number>
      </plugin>
    </gazebo>

    <!-- Create AGV Tray plugin -->
    <gazebo>
      <plugin filename="libAGVTrayPlugin.so" name="${agv_number}_tray_plugin">
        <ros>
        </ros>
        <agv_tray_link>${agv_number}_tray</agv_tray_link>
        <agv_number>${agv_number}</agv_number>
      </plugin>
    </gazebo>

  </xacro:macro>
</robot>